[2025-01-01T21:20:05.661+0000] {local_task_job_runner.py:123} INFO - ::group::Pre task execution logs
[2025-01-01T21:20:05.675+0000] {taskinstance.py:2613} INFO - Dependencies all met for dep_context=non-requeueable deps ti=<TaskInstance: prediction_dag_v1.task_to_fail manual__2025-01-01T21:19:54.165599+00:00 [queued]>
[2025-01-01T21:20:05.685+0000] {taskinstance.py:2613} INFO - Dependencies all met for dep_context=requeueable deps ti=<TaskInstance: prediction_dag_v1.task_to_fail manual__2025-01-01T21:19:54.165599+00:00 [queued]>
[2025-01-01T21:20:05.686+0000] {taskinstance.py:2866} INFO - Starting attempt 2 of 2
[2025-01-01T21:20:05.698+0000] {taskinstance.py:2889} INFO - Executing <Task(_PythonDecoratedOperator): task_to_fail> on 2025-01-01 21:19:54.165599+00:00
[2025-01-01T21:20:05.705+0000] {warnings.py:112} WARNING - /home/***/.local/lib/python3.12/site-packages/***/task/task_runner/standard_task_runner.py:70: DeprecationWarning: This process (pid=574) is multi-threaded, use of fork() may lead to deadlocks in the child.
  pid = os.fork()

[2025-01-01T21:20:05.706+0000] {standard_task_runner.py:72} INFO - Started process 576 to run task
[2025-01-01T21:20:05.707+0000] {standard_task_runner.py:104} INFO - Running: ['***', 'tasks', 'run', 'prediction_dag_v1', 'task_to_fail', 'manual__2025-01-01T21:19:54.165599+00:00', '--job-id', '13', '--raw', '--subdir', 'DAGS_FOLDER/02_prediction/02_prediction_v1.py', '--cfg-path', '/tmp/tmp7tfopxnm']
[2025-01-01T21:20:05.708+0000] {standard_task_runner.py:105} INFO - Job 13: Subtask task_to_fail
[2025-01-01T21:20:05.772+0000] {task_command.py:467} INFO - Running <TaskInstance: prediction_dag_v1.task_to_fail manual__2025-01-01T21:19:54.165599+00:00 [running]> on host 935cb972f608
[2025-01-01T21:20:05.857+0000] {taskinstance.py:3132} INFO - Exporting env vars: AIRFLOW_CTX_DAG_OWNER='cm' AIRFLOW_CTX_DAG_ID='prediction_dag_v1' AIRFLOW_CTX_TASK_ID='task_to_fail' AIRFLOW_CTX_EXECUTION_DATE='2025-01-01T21:19:54.165599+00:00' AIRFLOW_CTX_TRY_NUMBER='2' AIRFLOW_CTX_DAG_RUN_ID='manual__2025-01-01T21:19:54.165599+00:00'
[2025-01-01T21:20:05.859+0000] {logging_mixin.py:190} INFO - Task instance is in running state
[2025-01-01T21:20:05.860+0000] {logging_mixin.py:190} INFO -  Previous state of the Task instance: queued
[2025-01-01T21:20:05.860+0000] {logging_mixin.py:190} INFO - Current task name:task_to_fail state:running start_date:2025-01-01 21:20:05.677080+00:00
[2025-01-01T21:20:05.861+0000] {logging_mixin.py:190} INFO - Dag name:prediction_dag_v1 and current dag run status:running
[2025-01-01T21:20:05.862+0000] {taskinstance.py:731} INFO - ::endgroup::
[2025-01-01T21:20:05.863+0000] {taskinstance.py:3311} ERROR - Task failed with exception
Traceback (most recent call last):
  File "/home/airflow/.local/lib/python3.12/site-packages/airflow/models/taskinstance.py", line 767, in _execute_task
    result = _execute_callable(context=context, **execute_callable_kwargs)
             ^^^^^^^^^^^^^^^^^^^^^^^^^^^^^^^^^^^^^^^^^^^^^^^^^^^^^^^^^^^^^
  File "/home/airflow/.local/lib/python3.12/site-packages/airflow/models/taskinstance.py", line 733, in _execute_callable
    return ExecutionCallableRunner(
           ^^^^^^^^^^^^^^^^^^^^^^^^
  File "/home/airflow/.local/lib/python3.12/site-packages/airflow/utils/operator_helpers.py", line 252, in run
    return self.func(*args, **kwargs)
           ^^^^^^^^^^^^^^^^^^^^^^^^^^
  File "/home/airflow/.local/lib/python3.12/site-packages/airflow/models/baseoperator.py", line 417, in wrapper
    return func(self, *args, **kwargs)
           ^^^^^^^^^^^^^^^^^^^^^^^^^^^
  File "/home/airflow/.local/lib/python3.12/site-packages/airflow/decorators/base.py", line 266, in execute
    return_value = super().execute(context)
                   ^^^^^^^^^^^^^^^^^^^^^^^^
  File "/home/airflow/.local/lib/python3.12/site-packages/airflow/models/baseoperator.py", line 417, in wrapper
    return func(self, *args, **kwargs)
           ^^^^^^^^^^^^^^^^^^^^^^^^^^^
  File "/home/airflow/.local/lib/python3.12/site-packages/airflow/operators/python.py", line 238, in execute
    return_value = self.execute_callable()
                   ^^^^^^^^^^^^^^^^^^^^^^^
  File "/home/airflow/.local/lib/python3.12/site-packages/airflow/operators/python.py", line 256, in execute_callable
    return runner.run(*self.op_args, **self.op_kwargs)
           ^^^^^^^^^^^^^^^^^^^^^^^^^^^^^^^^^^^^^^^^^^^
  File "/home/airflow/.local/lib/python3.12/site-packages/airflow/utils/operator_helpers.py", line 252, in run
    return self.func(*args, **kwargs)
           ^^^^^^^^^^^^^^^^^^^^^^^^^^
  File "/opt/airflow/dags/common/prediction_task.py", line 127, in task_to_fail
    raise AirflowFailException("error")
          ^^^^^^^^^^^^^^^^^^^^
NameError: name 'AirflowFailException' is not defined
[2025-01-01T21:20:05.885+0000] {logging_mixin.py:190} INFO - Task instance in failure state
[2025-01-01T21:20:05.886+0000] {logging_mixin.py:190} INFO - Task start:2025-01-01 21:20:05.677080+00:00 end:2025-01-01 21:20:05.885008+00:00 duration:0.207928
[2025-01-01T21:20:05.887+0000] {logging_mixin.py:190} INFO - Task:<Task(_PythonDecoratedOperator): task_to_fail> dag:<DAG: prediction_dag_v1> dagrun:<DagRun prediction_dag_v1 @ 2025-01-01 21:19:54.165599+00:00: manual__2025-01-01T21:19:54.165599+00:00, state:running, queued_at: 2025-01-01 21:19:54.197100+00:00. externally triggered: True>
[2025-01-01T21:20:05.888+0000] {logging_mixin.py:190} INFO - Failure caused by name 'AirflowFailException' is not defined
[2025-01-01T21:20:05.889+0000] {taskinstance.py:1225} INFO - Marking task as FAILED. dag_id=prediction_dag_v1, task_id=task_to_fail, run_id=manual__2025-01-01T21:19:54.165599+00:00, execution_date=20250101T211954, start_date=20250101T212005, end_date=20250101T212005
[2025-01-01T21:20:05.900+0000] {taskinstance.py:340} INFO - ::group::Post task execution logs
[2025-01-01T21:20:05.901+0000] {standard_task_runner.py:124} ERROR - Failed to execute job 13 for task task_to_fail (name 'AirflowFailException' is not defined; 576)
Traceback (most recent call last):
  File "/home/airflow/.local/lib/python3.12/site-packages/airflow/task/task_runner/standard_task_runner.py", line 117, in _start_by_fork
    ret = args.func(args, dag=self.dag)
          ^^^^^^^^^^^^^^^^^^^^^^^^^^^^^
  File "/home/airflow/.local/lib/python3.12/site-packages/airflow/cli/cli_config.py", line 49, in command
    return func(*args, **kwargs)
           ^^^^^^^^^^^^^^^^^^^^^
  File "/home/airflow/.local/lib/python3.12/site-packages/airflow/utils/cli.py", line 116, in wrapper
    return f(*args, **kwargs)
           ^^^^^^^^^^^^^^^^^^
  File "/home/airflow/.local/lib/python3.12/site-packages/airflow/cli/commands/task_command.py", line 483, in task_run
    task_return_code = _run_task_by_selected_method(args, _dag, ti)
                       ^^^^^^^^^^^^^^^^^^^^^^^^^^^^^^^^^^^^^^^^^^^^
  File "/home/airflow/.local/lib/python3.12/site-packages/airflow/cli/commands/task_command.py", line 256, in _run_task_by_selected_method
    return _run_raw_task(args, ti)
           ^^^^^^^^^^^^^^^^^^^^^^^
  File "/home/airflow/.local/lib/python3.12/site-packages/airflow/cli/commands/task_command.py", line 341, in _run_raw_task
    return ti._run_raw_task(
           ^^^^^^^^^^^^^^^^^
  File "/home/airflow/.local/lib/python3.12/site-packages/airflow/utils/session.py", line 97, in wrapper
    return func(*args, session=session, **kwargs)
           ^^^^^^^^^^^^^^^^^^^^^^^^^^^^^^^^^^^^^^
  File "/home/airflow/.local/lib/python3.12/site-packages/airflow/models/taskinstance.py", line 3005, in _run_raw_task
    return _run_raw_task(
           ^^^^^^^^^^^^^^
  File "/home/airflow/.local/lib/python3.12/site-packages/airflow/models/taskinstance.py", line 273, in _run_raw_task
    TaskInstance._execute_task_with_callbacks(
  File "/home/airflow/.local/lib/python3.12/site-packages/airflow/models/taskinstance.py", line 3159, in _execute_task_with_callbacks
    result = self._execute_task(context, task_orig)
             ^^^^^^^^^^^^^^^^^^^^^^^^^^^^^^^^^^^^^^
  File "/home/airflow/.local/lib/python3.12/site-packages/airflow/models/taskinstance.py", line 3183, in _execute_task
    return _execute_task(self, context, task_orig)
           ^^^^^^^^^^^^^^^^^^^^^^^^^^^^^^^^^^^^^^^
  File "/home/airflow/.local/lib/python3.12/site-packages/airflow/models/taskinstance.py", line 767, in _execute_task
    result = _execute_callable(context=context, **execute_callable_kwargs)
             ^^^^^^^^^^^^^^^^^^^^^^^^^^^^^^^^^^^^^^^^^^^^^^^^^^^^^^^^^^^^^
  File "/home/airflow/.local/lib/python3.12/site-packages/airflow/models/taskinstance.py", line 733, in _execute_callable
    return ExecutionCallableRunner(
           ^^^^^^^^^^^^^^^^^^^^^^^^
  File "/home/airflow/.local/lib/python3.12/site-packages/airflow/utils/operator_helpers.py", line 252, in run
    return self.func(*args, **kwargs)
           ^^^^^^^^^^^^^^^^^^^^^^^^^^
  File "/home/airflow/.local/lib/python3.12/site-packages/airflow/models/baseoperator.py", line 417, in wrapper
    return func(self, *args, **kwargs)
           ^^^^^^^^^^^^^^^^^^^^^^^^^^^
  File "/home/airflow/.local/lib/python3.12/site-packages/airflow/decorators/base.py", line 266, in execute
    return_value = super().execute(context)
                   ^^^^^^^^^^^^^^^^^^^^^^^^
  File "/home/airflow/.local/lib/python3.12/site-packages/airflow/models/baseoperator.py", line 417, in wrapper
    return func(self, *args, **kwargs)
           ^^^^^^^^^^^^^^^^^^^^^^^^^^^
  File "/home/airflow/.local/lib/python3.12/site-packages/airflow/operators/python.py", line 238, in execute
    return_value = self.execute_callable()
                   ^^^^^^^^^^^^^^^^^^^^^^^
  File "/home/airflow/.local/lib/python3.12/site-packages/airflow/operators/python.py", line 256, in execute_callable
    return runner.run(*self.op_args, **self.op_kwargs)
           ^^^^^^^^^^^^^^^^^^^^^^^^^^^^^^^^^^^^^^^^^^^
  File "/home/airflow/.local/lib/python3.12/site-packages/airflow/utils/operator_helpers.py", line 252, in run
    return self.func(*args, **kwargs)
           ^^^^^^^^^^^^^^^^^^^^^^^^^^
  File "/opt/airflow/dags/common/prediction_task.py", line 127, in task_to_fail
    raise AirflowFailException("error")
          ^^^^^^^^^^^^^^^^^^^^
NameError: name 'AirflowFailException' is not defined
[2025-01-01T21:20:05.923+0000] {local_task_job_runner.py:266} INFO - Task exited with return code 1
[2025-01-01T21:20:05.938+0000] {taskinstance.py:3895} INFO - 0 downstream tasks scheduled from follow-on schedule check
[2025-01-01T21:20:05.941+0000] {local_task_job_runner.py:245} INFO - ::endgroup::
