[2025-01-01T23:43:02.406+0000] {local_task_job_runner.py:123} INFO - ::group::Pre task execution logs
[2025-01-01T23:43:02.425+0000] {taskinstance.py:2613} INFO - Dependencies all met for dep_context=non-requeueable deps ti=<TaskInstance: prediction_dag_v1.evaluate_status manual__2025-01-01T23:42:28.302681+00:00 [queued]>
[2025-01-01T23:43:02.434+0000] {taskinstance.py:2613} INFO - Dependencies all met for dep_context=requeueable deps ti=<TaskInstance: prediction_dag_v1.evaluate_status manual__2025-01-01T23:42:28.302681+00:00 [queued]>
[2025-01-01T23:43:02.435+0000] {taskinstance.py:2866} INFO - Starting attempt 1 of 2
[2025-01-01T23:43:02.448+0000] {taskinstance.py:2889} INFO - Executing <Task(_PythonDecoratedOperator): evaluate_status> on 2025-01-01 23:42:28.302681+00:00
[2025-01-01T23:43:02.456+0000] {warnings.py:112} WARNING - /home/***/.local/lib/python3.12/site-packages/***/task/task_runner/standard_task_runner.py:70: DeprecationWarning: This process (pid=875) is multi-threaded, use of fork() may lead to deadlocks in the child.
  pid = os.fork()

[2025-01-01T23:43:02.458+0000] {standard_task_runner.py:72} INFO - Started process 877 to run task
[2025-01-01T23:43:02.458+0000] {standard_task_runner.py:104} INFO - Running: ['***', 'tasks', 'run', 'prediction_dag_v1', 'evaluate_status', 'manual__2025-01-01T23:42:28.302681+00:00', '--job-id', '32', '--raw', '--subdir', 'DAGS_FOLDER/02_prediction/02_prediction_v1.py', '--cfg-path', '/tmp/tmpv9y2faww']
[2025-01-01T23:43:02.459+0000] {standard_task_runner.py:105} INFO - Job 32: Subtask evaluate_status
[2025-01-01T23:43:02.512+0000] {task_command.py:467} INFO - Running <TaskInstance: prediction_dag_v1.evaluate_status manual__2025-01-01T23:42:28.302681+00:00 [running]> on host 24eea4b1b7f8
[2025-01-01T23:43:02.597+0000] {taskinstance.py:3132} INFO - Exporting env vars: AIRFLOW_CTX_DAG_OWNER='cm' AIRFLOW_CTX_DAG_ID='prediction_dag_v1' AIRFLOW_CTX_TASK_ID='evaluate_status' AIRFLOW_CTX_EXECUTION_DATE='2025-01-01T23:42:28.302681+00:00' AIRFLOW_CTX_TRY_NUMBER='1' AIRFLOW_CTX_DAG_RUN_ID='manual__2025-01-01T23:42:28.302681+00:00'
[2025-01-01T23:43:02.599+0000] {logging_mixin.py:190} INFO - Task instance is in running state
[2025-01-01T23:43:02.605+0000] {logging_mixin.py:190} INFO -  Previous state of the Task instance: queued
[2025-01-01T23:43:02.606+0000] {logging_mixin.py:190} INFO - Current task name:evaluate_status state:running start_date:2025-01-01 23:43:02.426856+00:00
[2025-01-01T23:43:02.607+0000] {logging_mixin.py:190} INFO - Dag name:prediction_dag_v1 and current dag run status:running
[2025-01-01T23:43:02.608+0000] {taskinstance.py:731} INFO - ::endgroup::
[2025-01-01T23:43:02.615+0000] {crypto.py:82} WARNING - empty cryptography key - values will not be stored encrypted.
[2025-01-01T23:43:02.619+0000] {taskinstance.py:3311} ERROR - Task failed with exception
Traceback (most recent call last):
  File "/home/airflow/.local/lib/python3.12/site-packages/airflow/models/taskinstance.py", line 767, in _execute_task
    result = _execute_callable(context=context, **execute_callable_kwargs)
             ^^^^^^^^^^^^^^^^^^^^^^^^^^^^^^^^^^^^^^^^^^^^^^^^^^^^^^^^^^^^^
  File "/home/airflow/.local/lib/python3.12/site-packages/airflow/models/taskinstance.py", line 733, in _execute_callable
    return ExecutionCallableRunner(
           ^^^^^^^^^^^^^^^^^^^^^^^^
  File "/home/airflow/.local/lib/python3.12/site-packages/airflow/utils/operator_helpers.py", line 252, in run
    return self.func(*args, **kwargs)
           ^^^^^^^^^^^^^^^^^^^^^^^^^^
  File "/home/airflow/.local/lib/python3.12/site-packages/airflow/models/baseoperator.py", line 417, in wrapper
    return func(self, *args, **kwargs)
           ^^^^^^^^^^^^^^^^^^^^^^^^^^^
  File "/home/airflow/.local/lib/python3.12/site-packages/airflow/decorators/base.py", line 266, in execute
    return_value = super().execute(context)
                   ^^^^^^^^^^^^^^^^^^^^^^^^
  File "/home/airflow/.local/lib/python3.12/site-packages/airflow/models/baseoperator.py", line 417, in wrapper
    return func(self, *args, **kwargs)
           ^^^^^^^^^^^^^^^^^^^^^^^^^^^
  File "/home/airflow/.local/lib/python3.12/site-packages/airflow/operators/python.py", line 238, in execute
    return_value = self.execute_callable()
                   ^^^^^^^^^^^^^^^^^^^^^^^
  File "/home/airflow/.local/lib/python3.12/site-packages/airflow/operators/python.py", line 256, in execute_callable
    return runner.run(*self.op_args, **self.op_kwargs)
           ^^^^^^^^^^^^^^^^^^^^^^^^^^^^^^^^^^^^^^^^^^^
  File "/home/airflow/.local/lib/python3.12/site-packages/airflow/utils/operator_helpers.py", line 252, in run
    return self.func(*args, **kwargs)
           ^^^^^^^^^^^^^^^^^^^^^^^^^^
  File "/opt/airflow/dags/common/global_task.py", line 14, in evaluate_status
    raise AirflowFailException("error")#task_to_fail()
    ^^^^^^^^^^^^^^^^^^^^^^^^^^^^^^^^^^^
airflow.exceptions.AirflowFailException: error
[2025-01-01T23:43:02.638+0000] {logging_mixin.py:190} INFO - Task instance in failure state
[2025-01-01T23:43:02.639+0000] {logging_mixin.py:190} INFO - Task start:2025-01-01 23:43:02.426856+00:00 end:2025-01-01 23:43:02.637972+00:00 duration:0.211116
[2025-01-01T23:43:02.640+0000] {logging_mixin.py:190} INFO - Task:<Task(_PythonDecoratedOperator): evaluate_status> dag:<DAG: prediction_dag_v1> dagrun:<DagRun prediction_dag_v1 @ 2025-01-01 23:42:28.302681+00:00: manual__2025-01-01T23:42:28.302681+00:00, state:running, queued_at: 2025-01-01 23:42:28.310950+00:00. externally triggered: True>
[2025-01-01T23:43:02.640+0000] {logging_mixin.py:190} INFO - Failure caused by error
[2025-01-01T23:43:02.641+0000] {taskinstance.py:1225} INFO - Immediate failure requested. Marking task as FAILED. dag_id=prediction_dag_v1, task_id=evaluate_status, run_id=manual__2025-01-01T23:42:28.302681+00:00, execution_date=20250101T234228, start_date=20250101T234302, end_date=20250101T234302
[2025-01-01T23:43:02.653+0000] {taskinstance.py:340} INFO - ::group::Post task execution logs
[2025-01-01T23:43:02.654+0000] {standard_task_runner.py:124} ERROR - Failed to execute job 32 for task evaluate_status (error; 877)
Traceback (most recent call last):
  File "/home/airflow/.local/lib/python3.12/site-packages/airflow/task/task_runner/standard_task_runner.py", line 117, in _start_by_fork
    ret = args.func(args, dag=self.dag)
          ^^^^^^^^^^^^^^^^^^^^^^^^^^^^^
  File "/home/airflow/.local/lib/python3.12/site-packages/airflow/cli/cli_config.py", line 49, in command
    return func(*args, **kwargs)
           ^^^^^^^^^^^^^^^^^^^^^
  File "/home/airflow/.local/lib/python3.12/site-packages/airflow/utils/cli.py", line 116, in wrapper
    return f(*args, **kwargs)
           ^^^^^^^^^^^^^^^^^^
  File "/home/airflow/.local/lib/python3.12/site-packages/airflow/cli/commands/task_command.py", line 483, in task_run
    task_return_code = _run_task_by_selected_method(args, _dag, ti)
                       ^^^^^^^^^^^^^^^^^^^^^^^^^^^^^^^^^^^^^^^^^^^^
  File "/home/airflow/.local/lib/python3.12/site-packages/airflow/cli/commands/task_command.py", line 256, in _run_task_by_selected_method
    return _run_raw_task(args, ti)
           ^^^^^^^^^^^^^^^^^^^^^^^
  File "/home/airflow/.local/lib/python3.12/site-packages/airflow/cli/commands/task_command.py", line 341, in _run_raw_task
    return ti._run_raw_task(
           ^^^^^^^^^^^^^^^^^
  File "/home/airflow/.local/lib/python3.12/site-packages/airflow/utils/session.py", line 97, in wrapper
    return func(*args, session=session, **kwargs)
           ^^^^^^^^^^^^^^^^^^^^^^^^^^^^^^^^^^^^^^
  File "/home/airflow/.local/lib/python3.12/site-packages/airflow/models/taskinstance.py", line 3005, in _run_raw_task
    return _run_raw_task(
           ^^^^^^^^^^^^^^
  File "/home/airflow/.local/lib/python3.12/site-packages/airflow/models/taskinstance.py", line 273, in _run_raw_task
    TaskInstance._execute_task_with_callbacks(
  File "/home/airflow/.local/lib/python3.12/site-packages/airflow/models/taskinstance.py", line 3159, in _execute_task_with_callbacks
    result = self._execute_task(context, task_orig)
             ^^^^^^^^^^^^^^^^^^^^^^^^^^^^^^^^^^^^^^
  File "/home/airflow/.local/lib/python3.12/site-packages/airflow/models/taskinstance.py", line 3183, in _execute_task
    return _execute_task(self, context, task_orig)
           ^^^^^^^^^^^^^^^^^^^^^^^^^^^^^^^^^^^^^^^
  File "/home/airflow/.local/lib/python3.12/site-packages/airflow/models/taskinstance.py", line 767, in _execute_task
    result = _execute_callable(context=context, **execute_callable_kwargs)
             ^^^^^^^^^^^^^^^^^^^^^^^^^^^^^^^^^^^^^^^^^^^^^^^^^^^^^^^^^^^^^
  File "/home/airflow/.local/lib/python3.12/site-packages/airflow/models/taskinstance.py", line 733, in _execute_callable
    return ExecutionCallableRunner(
           ^^^^^^^^^^^^^^^^^^^^^^^^
  File "/home/airflow/.local/lib/python3.12/site-packages/airflow/utils/operator_helpers.py", line 252, in run
    return self.func(*args, **kwargs)
           ^^^^^^^^^^^^^^^^^^^^^^^^^^
  File "/home/airflow/.local/lib/python3.12/site-packages/airflow/models/baseoperator.py", line 417, in wrapper
    return func(self, *args, **kwargs)
           ^^^^^^^^^^^^^^^^^^^^^^^^^^^
  File "/home/airflow/.local/lib/python3.12/site-packages/airflow/decorators/base.py", line 266, in execute
    return_value = super().execute(context)
                   ^^^^^^^^^^^^^^^^^^^^^^^^
  File "/home/airflow/.local/lib/python3.12/site-packages/airflow/models/baseoperator.py", line 417, in wrapper
    return func(self, *args, **kwargs)
           ^^^^^^^^^^^^^^^^^^^^^^^^^^^
  File "/home/airflow/.local/lib/python3.12/site-packages/airflow/operators/python.py", line 238, in execute
    return_value = self.execute_callable()
                   ^^^^^^^^^^^^^^^^^^^^^^^
  File "/home/airflow/.local/lib/python3.12/site-packages/airflow/operators/python.py", line 256, in execute_callable
    return runner.run(*self.op_args, **self.op_kwargs)
           ^^^^^^^^^^^^^^^^^^^^^^^^^^^^^^^^^^^^^^^^^^^
  File "/home/airflow/.local/lib/python3.12/site-packages/airflow/utils/operator_helpers.py", line 252, in run
    return self.func(*args, **kwargs)
           ^^^^^^^^^^^^^^^^^^^^^^^^^^
  File "/opt/airflow/dags/common/global_task.py", line 14, in evaluate_status
    raise AirflowFailException("error")#task_to_fail()
    ^^^^^^^^^^^^^^^^^^^^^^^^^^^^^^^^^^^
airflow.exceptions.AirflowFailException: error
[2025-01-01T23:43:02.674+0000] {local_task_job_runner.py:266} INFO - Task exited with return code 1
[2025-01-01T23:43:02.689+0000] {taskinstance.py:3895} INFO - 0 downstream tasks scheduled from follow-on schedule check
[2025-01-01T23:43:02.694+0000] {local_task_job_runner.py:245} INFO - ::endgroup::
