[2025-01-01T18:04:53.497+0000] {local_task_job_runner.py:123} INFO - ::group::Pre task execution logs
[2025-01-01T18:04:53.524+0000] {taskinstance.py:2613} INFO - Dependencies all met for dep_context=non-requeueable deps ti=<TaskInstance: prediction_dag_v1.predict_model manual__2025-01-01T18:04:46.406585+00:00 [queued]>
[2025-01-01T18:04:53.535+0000] {taskinstance.py:2613} INFO - Dependencies all met for dep_context=requeueable deps ti=<TaskInstance: prediction_dag_v1.predict_model manual__2025-01-01T18:04:46.406585+00:00 [queued]>
[2025-01-01T18:04:53.536+0000] {taskinstance.py:2866} INFO - Starting attempt 1 of 2
[2025-01-01T18:04:53.564+0000] {taskinstance.py:2889} INFO - Executing <Task(_PythonVirtualenvDecoratedOperator): predict_model> on 2025-01-01 18:04:46.406585+00:00
[2025-01-01T18:04:53.573+0000] {warnings.py:112} WARNING - /home/***/.local/lib/python3.12/site-packages/***/task/task_runner/standard_task_runner.py:70: DeprecationWarning: This process (pid=1261) is multi-threaded, use of fork() may lead to deadlocks in the child.
  pid = os.fork()

[2025-01-01T18:04:53.575+0000] {standard_task_runner.py:72} INFO - Started process 1263 to run task
[2025-01-01T18:04:53.576+0000] {standard_task_runner.py:104} INFO - Running: ['***', 'tasks', 'run', 'prediction_dag_v1', 'predict_model', 'manual__2025-01-01T18:04:46.406585+00:00', '--job-id', '16', '--raw', '--subdir', 'DAGS_FOLDER/02_prediction/02_prediction_v1.py', '--cfg-path', '/tmp/tmp2m2y02sl']
[2025-01-01T18:04:53.579+0000] {standard_task_runner.py:105} INFO - Job 16: Subtask predict_model
[2025-01-01T18:04:53.637+0000] {task_command.py:467} INFO - Running <TaskInstance: prediction_dag_v1.predict_model manual__2025-01-01T18:04:46.406585+00:00 [running]> on host cbeec914397d
[2025-01-01T18:04:54.180+0000] {taskinstance.py:3132} INFO - Exporting env vars: AIRFLOW_CTX_DAG_OWNER='cm' AIRFLOW_CTX_DAG_ID='prediction_dag_v1' AIRFLOW_CTX_TASK_ID='predict_model' AIRFLOW_CTX_EXECUTION_DATE='2025-01-01T18:04:46.406585+00:00' AIRFLOW_CTX_TRY_NUMBER='1' AIRFLOW_CTX_DAG_RUN_ID='manual__2025-01-01T18:04:46.406585+00:00'
[2025-01-01T18:04:54.182+0000] {logging_mixin.py:190} INFO - Task instance is in running state
[2025-01-01T18:04:54.183+0000] {logging_mixin.py:190} INFO -  Previous state of the Task instance: queued
[2025-01-01T18:04:54.184+0000] {logging_mixin.py:190} INFO - Current task name:predict_model state:running start_date:2025-01-01 18:04:53.525068+00:00
[2025-01-01T18:04:54.185+0000] {logging_mixin.py:190} INFO - Dag name:prediction_dag_v1 and current dag run status:running
[2025-01-01T18:04:54.186+0000] {taskinstance.py:731} INFO - ::endgroup::
[2025-01-01T18:04:54.188+0000] {process_utils.py:186} INFO - Executing cmd: /home/***/.local/bin/python -m virtualenv /tmp/venvdcnutp80 --system-site-packages --python=python
[2025-01-01T18:04:54.189+0000] {process_utils.py:190} INFO - Output:
[2025-01-01T18:04:55.026+0000] {process_utils.py:194} INFO - created virtual environment CPython3.12.7.final.0-64 in 225ms
[2025-01-01T18:04:55.027+0000] {process_utils.py:194} INFO -   creator CPython3Posix(dest=/tmp/venvdcnutp80, clear=False, no_vcs_ignore=False, global=True)
[2025-01-01T18:04:55.028+0000] {process_utils.py:194} INFO -   seeder FromAppData(download=False, pip=bundle, via=copy, app_data_dir=/home/***/.local/share/virtualenv)
[2025-01-01T18:04:55.029+0000] {process_utils.py:194} INFO -     added seed packages: pip==24.3.1
[2025-01-01T18:04:55.030+0000] {process_utils.py:194} INFO -   activators BashActivator,CShellActivator,FishActivator,NushellActivator,PowerShellActivator,PythonActivator
[2025-01-01T18:04:55.053+0000] {process_utils.py:186} INFO - Executing cmd: /tmp/venvdcnutp80/bin/pip install -r /tmp/venvdcnutp80/requirements.txt
[2025-01-01T18:04:55.054+0000] {process_utils.py:190} INFO - Output:
[2025-01-01T18:04:57.237+0000] {process_utils.py:194} INFO - Collecting feature-engine==1.8.2 (from -r /tmp/venvdcnutp80/requirements.txt (line 1))
[2025-01-01T18:04:57.239+0000] {process_utils.py:194} INFO -   Using cached feature_engine-1.8.2-py2.py3-none-any.whl.metadata (9.9 kB)
[2025-01-01T18:04:57.326+0000] {process_utils.py:194} INFO - Collecting joblib==1.3.2 (from -r /tmp/venvdcnutp80/requirements.txt (line 2))
[2025-01-01T18:04:57.328+0000] {process_utils.py:194} INFO -   Using cached joblib-1.3.2-py3-none-any.whl.metadata (5.4 kB)
[2025-01-01T18:04:57.330+0000] {process_utils.py:194} INFO - Requirement already satisfied: numpy==1.26.4 in /home/***/.local/lib/python3.12/site-packages (from -r /tmp/venvdcnutp80/requirements.txt (line 3)) (1.26.4)
[2025-01-01T18:04:57.517+0000] {process_utils.py:194} INFO - Collecting pandas==2.2.3 (from -r /tmp/venvdcnutp80/requirements.txt (line 4))
[2025-01-01T18:04:57.519+0000] {process_utils.py:194} INFO -   Using cached pandas-2.2.3-cp312-cp312-manylinux_2_17_x86_64.manylinux2014_x86_64.whl.metadata (89 kB)
[2025-01-01T18:04:57.560+0000] {process_utils.py:194} INFO - Requirement already satisfied: pendulum in /home/***/.local/lib/python3.12/site-packages (from -r /tmp/venvdcnutp80/requirements.txt (line 5)) (3.0.0)
[2025-01-01T18:04:57.690+0000] {process_utils.py:194} INFO - Collecting scikit-learn==1.5.2 (from -r /tmp/venvdcnutp80/requirements.txt (line 6))
[2025-01-01T18:04:57.692+0000] {process_utils.py:194} INFO -   Using cached scikit_learn-1.5.2-cp312-cp312-manylinux_2_17_x86_64.manylinux2014_x86_64.whl.metadata (13 kB)
[2025-01-01T18:04:57.861+0000] {process_utils.py:194} INFO - Collecting scipy>=1.4.1 (from feature-engine==1.8.2->-r /tmp/venvdcnutp80/requirements.txt (line 1))
[2025-01-01T18:04:57.863+0000] {process_utils.py:194} INFO -   Using cached scipy-1.14.1-cp312-cp312-manylinux_2_17_x86_64.manylinux2014_x86_64.whl.metadata (60 kB)
[2025-01-01T18:04:58.061+0000] {process_utils.py:194} INFO - Collecting statsmodels>=0.11.1 (from feature-engine==1.8.2->-r /tmp/venvdcnutp80/requirements.txt (line 1))
[2025-01-01T18:04:58.064+0000] {process_utils.py:194} INFO -   Using cached statsmodels-0.14.4-cp312-cp312-manylinux_2_17_x86_64.manylinux2014_x86_64.whl.metadata (9.2 kB)
[2025-01-01T18:04:58.082+0000] {process_utils.py:194} INFO - Requirement already satisfied: python-dateutil>=2.8.2 in /home/***/.local/lib/python3.12/site-packages (from pandas==2.2.3->-r /tmp/venvdcnutp80/requirements.txt (line 4)) (2.9.0.post0)
[2025-01-01T18:04:58.083+0000] {process_utils.py:194} INFO - Requirement already satisfied: pytz>=2020.1 in /home/***/.local/lib/python3.12/site-packages (from pandas==2.2.3->-r /tmp/venvdcnutp80/requirements.txt (line 4)) (2024.2)
[2025-01-01T18:04:58.084+0000] {process_utils.py:194} INFO - Requirement already satisfied: tzdata>=2022.7 in /home/***/.local/lib/python3.12/site-packages (from pandas==2.2.3->-r /tmp/venvdcnutp80/requirements.txt (line 4)) (2024.2)
[2025-01-01T18:04:58.125+0000] {process_utils.py:194} INFO - Collecting threadpoolctl>=3.1.0 (from scikit-learn==1.5.2->-r /tmp/venvdcnutp80/requirements.txt (line 6))
[2025-01-01T18:04:58.127+0000] {process_utils.py:194} INFO -   Using cached threadpoolctl-3.5.0-py3-none-any.whl.metadata (13 kB)
[2025-01-01T18:04:58.134+0000] {process_utils.py:194} INFO - Requirement already satisfied: time-machine>=2.6.0 in /home/***/.local/lib/python3.12/site-packages (from pendulum->-r /tmp/venvdcnutp80/requirements.txt (line 5)) (2.16.0)
[2025-01-01T18:04:58.139+0000] {process_utils.py:194} INFO - Requirement already satisfied: six>=1.5 in /home/***/.local/lib/python3.12/site-packages (from python-dateutil>=2.8.2->pandas==2.2.3->-r /tmp/venvdcnutp80/requirements.txt (line 4)) (1.16.0)
[2025-01-01T18:04:58.281+0000] {process_utils.py:194} INFO - Collecting patsy>=0.5.6 (from statsmodels>=0.11.1->feature-engine==1.8.2->-r /tmp/venvdcnutp80/requirements.txt (line 1))
[2025-01-01T18:04:58.283+0000] {process_utils.py:194} INFO -   Using cached patsy-1.0.1-py2.py3-none-any.whl.metadata (3.3 kB)
[2025-01-01T18:04:58.288+0000] {process_utils.py:194} INFO - Requirement already satisfied: packaging>=21.3 in /home/***/.local/lib/python3.12/site-packages (from statsmodels>=0.11.1->feature-engine==1.8.2->-r /tmp/venvdcnutp80/requirements.txt (line 1)) (24.1)
[2025-01-01T18:04:58.301+0000] {process_utils.py:194} INFO - Using cached feature_engine-1.8.2-py2.py3-none-any.whl (374 kB)
[2025-01-01T18:04:58.304+0000] {process_utils.py:194} INFO - Using cached joblib-1.3.2-py3-none-any.whl (302 kB)
[2025-01-01T18:04:58.306+0000] {process_utils.py:194} INFO - Using cached pandas-2.2.3-cp312-cp312-manylinux_2_17_x86_64.manylinux2014_x86_64.whl (12.7 MB)
[2025-01-01T18:04:58.349+0000] {process_utils.py:194} INFO - Using cached scikit_learn-1.5.2-cp312-cp312-manylinux_2_17_x86_64.manylinux2014_x86_64.whl (12.9 MB)
[2025-01-01T18:04:58.369+0000] {process_utils.py:194} INFO - Using cached scipy-1.14.1-cp312-cp312-manylinux_2_17_x86_64.manylinux2014_x86_64.whl (40.8 MB)
[2025-01-01T18:04:58.475+0000] {process_utils.py:194} INFO - Using cached statsmodels-0.14.4-cp312-cp312-manylinux_2_17_x86_64.manylinux2014_x86_64.whl (10.7 MB)
[2025-01-01T18:04:58.501+0000] {process_utils.py:194} INFO - Using cached threadpoolctl-3.5.0-py3-none-any.whl (18 kB)
[2025-01-01T18:04:58.503+0000] {process_utils.py:194} INFO - Using cached patsy-1.0.1-py2.py3-none-any.whl (232 kB)
[2025-01-01T18:04:59.525+0000] {process_utils.py:194} INFO - Installing collected packages: threadpoolctl, scipy, patsy, joblib, scikit-learn, pandas, statsmodels, feature-engine
[2025-01-01T18:05:06.857+0000] {process_utils.py:194} INFO -   Attempting uninstall: pandas
[2025-01-01T18:05:06.871+0000] {process_utils.py:194} INFO -     Found existing installation: pandas 2.1.4
[2025-01-01T18:05:06.873+0000] {process_utils.py:194} INFO -     Not uninstalling pandas at /home/***/.local/lib/python3.12/site-packages, outside environment /tmp/venvdcnutp80
[2025-01-01T18:05:06.874+0000] {process_utils.py:194} INFO -     Can't uninstall 'pandas'. No files were found to uninstall.
[2025-01-01T18:05:17.306+0000] {process_utils.py:194} INFO - ERROR: pip's dependency resolver does not currently take into account all the packages that are installed. This behaviour is the source of the following dependency conflicts.
[2025-01-01T18:05:17.307+0000] {process_utils.py:194} INFO - apache-***-providers-google 10.25.0 requires pandas<2.2,>=2.1.2; python_version >= "3.9", but you have pandas 2.2.3 which is incompatible.
[2025-01-01T18:05:17.308+0000] {process_utils.py:194} INFO - apache-***-providers-snowflake 5.8.0 requires pandas<2.2,>=2.1.2; python_version >= "3.9", but you have pandas 2.2.3 which is incompatible.
[2025-01-01T18:05:17.309+0000] {process_utils.py:194} INFO - Successfully installed feature-engine-1.8.2 joblib-1.3.2 pandas-2.2.3 patsy-1.0.1 scikit-learn-1.5.2 scipy-1.14.1 statsmodels-0.14.4 threadpoolctl-3.5.0
[2025-01-01T18:05:17.633+0000] {python.py:513} INFO - Use 'pickle' as serializer.
[2025-01-01T18:05:17.660+0000] {process_utils.py:186} INFO - Executing cmd: /tmp/venvdcnutp80/bin/python /tmp/venv-callr_owk9sm/script.py /tmp/venv-callr_owk9sm/script.in /tmp/venv-callr_owk9sm/script.out /tmp/venv-callr_owk9sm/string_args.txt /tmp/venv-callr_owk9sm/termination.log
[2025-01-01T18:05:17.662+0000] {process_utils.py:190} INFO - Output:
[2025-01-01T18:05:19.426+0000] {process_utils.py:194} INFO - /home/***/.local/lib/python3.12/site-packages/***/configuration.py:859 FutureWarning: section/key [core/sql_alchemy_conn] has been deprecated, you should use[database/sql_alchemy_conn] instead. Please update your `conf.get*` call to use the new name
[2025-01-01T18:05:21.909+0000] {process_utils.py:194} INFO - Traceback (most recent call last):
[2025-01-01T18:05:21.910+0000] {process_utils.py:194} INFO -   File "/tmp/venv-callr_owk9sm/script.py", line 102, in <module>
[2025-01-01T18:05:21.911+0000] {process_utils.py:194} INFO -     res = task_predict_model(*arg_dict["args"], **arg_dict["kwargs"])
[2025-01-01T18:05:21.913+0000] {process_utils.py:194} INFO -           ^^^^^^^^^^^^^^^^^^^^^^^^^^^^^^^^^^^^^^^^^^^^^^^^^^^^^^^^^^^
[2025-01-01T18:05:21.913+0000] {process_utils.py:194} INFO -   File "/tmp/venv-callr_owk9sm/script.py", line 39, in task_predict_model
[2025-01-01T18:05:21.914+0000] {process_utils.py:194} INFO -     context = get_current_context()
[2025-01-01T18:05:21.915+0000] {process_utils.py:194} INFO -               ^^^^^^^^^^^^^^^^^^^
[2025-01-01T18:05:21.916+0000] {process_utils.py:194} INFO - NameError: name 'get_current_context' is not defined
[2025-01-01T18:05:22.921+0000] {taskinstance.py:3311} ERROR - Task failed with exception
Traceback (most recent call last):
  File "/home/airflow/.local/lib/python3.12/site-packages/airflow/models/taskinstance.py", line 767, in _execute_task
    result = _execute_callable(context=context, **execute_callable_kwargs)
             ^^^^^^^^^^^^^^^^^^^^^^^^^^^^^^^^^^^^^^^^^^^^^^^^^^^^^^^^^^^^^
  File "/home/airflow/.local/lib/python3.12/site-packages/airflow/models/taskinstance.py", line 733, in _execute_callable
    return ExecutionCallableRunner(
           ^^^^^^^^^^^^^^^^^^^^^^^^
  File "/home/airflow/.local/lib/python3.12/site-packages/airflow/utils/operator_helpers.py", line 252, in run
    return self.func(*args, **kwargs)
           ^^^^^^^^^^^^^^^^^^^^^^^^^^
  File "/home/airflow/.local/lib/python3.12/site-packages/airflow/models/baseoperator.py", line 417, in wrapper
    return func(self, *args, **kwargs)
           ^^^^^^^^^^^^^^^^^^^^^^^^^^^
  File "/home/airflow/.local/lib/python3.12/site-packages/airflow/decorators/base.py", line 266, in execute
    return_value = super().execute(context)
                   ^^^^^^^^^^^^^^^^^^^^^^^^
  File "/home/airflow/.local/lib/python3.12/site-packages/airflow/models/baseoperator.py", line 417, in wrapper
    return func(self, *args, **kwargs)
           ^^^^^^^^^^^^^^^^^^^^^^^^^^^
  File "/home/airflow/.local/lib/python3.12/site-packages/airflow/operators/python.py", line 505, in execute
    return super().execute(context=serializable_context)
           ^^^^^^^^^^^^^^^^^^^^^^^^^^^^^^^^^^^^^^^^^^^^^
  File "/home/airflow/.local/lib/python3.12/site-packages/airflow/models/baseoperator.py", line 417, in wrapper
    return func(self, *args, **kwargs)
           ^^^^^^^^^^^^^^^^^^^^^^^^^^^
  File "/home/airflow/.local/lib/python3.12/site-packages/airflow/operators/python.py", line 238, in execute
    return_value = self.execute_callable()
                   ^^^^^^^^^^^^^^^^^^^^^^^
  File "/home/airflow/.local/lib/python3.12/site-packages/airflow/operators/python.py", line 870, in execute_callable
    result = self._execute_python_callable_in_subprocess(python_path)
             ^^^^^^^^^^^^^^^^^^^^^^^^^^^^^^^^^^^^^^^^^^^^^^^^^^^^^^^^
  File "/home/airflow/.local/lib/python3.12/site-packages/airflow/operators/python.py", line 588, in _execute_python_callable_in_subprocess
    raise AirflowException(error_msg) from None
airflow.exceptions.AirflowException: Process returned non-zero exit status 1.
name 'get_current_context' is not defined
[2025-01-01T18:05:22.931+0000] {logging_mixin.py:190} INFO - Task instance in failure state
[2025-01-01T18:05:22.933+0000] {logging_mixin.py:190} INFO - Task start:2025-01-01 18:04:53.525068+00:00 end:2025-01-01 18:05:22.931478+00:00 duration:29.40641
[2025-01-01T18:05:22.934+0000] {logging_mixin.py:190} INFO - Task:<Task(_PythonVirtualenvDecoratedOperator): predict_model> dag:<DAG: prediction_dag_v1> dagrun:<DagRun prediction_dag_v1 @ 2025-01-01 18:04:46.406585+00:00: manual__2025-01-01T18:04:46.406585+00:00, state:running, queued_at: 2025-01-01 18:04:46.430319+00:00. externally triggered: True>
[2025-01-01T18:05:22.934+0000] {logging_mixin.py:190} INFO - Failure caused by Process returned non-zero exit status 1.
name 'get_current_context' is not defined
[2025-01-01T18:05:22.935+0000] {taskinstance.py:1225} INFO - Marking task as UP_FOR_RETRY. dag_id=prediction_dag_v1, task_id=predict_model, run_id=manual__2025-01-01T18:04:46.406585+00:00, execution_date=20250101T180446, start_date=20250101T180453, end_date=20250101T180522
[2025-01-01T18:05:22.978+0000] {taskinstance.py:340} INFO - ::group::Post task execution logs
[2025-01-01T18:05:22.987+0000] {standard_task_runner.py:124} ERROR - Failed to execute job 16 for task predict_model (Process returned non-zero exit status 1.
name 'get_current_context' is not defined; 1263)
Traceback (most recent call last):
  File "/home/airflow/.local/lib/python3.12/site-packages/airflow/task/task_runner/standard_task_runner.py", line 117, in _start_by_fork
    ret = args.func(args, dag=self.dag)
          ^^^^^^^^^^^^^^^^^^^^^^^^^^^^^
  File "/home/airflow/.local/lib/python3.12/site-packages/airflow/cli/cli_config.py", line 49, in command
    return func(*args, **kwargs)
           ^^^^^^^^^^^^^^^^^^^^^
  File "/home/airflow/.local/lib/python3.12/site-packages/airflow/utils/cli.py", line 116, in wrapper
    return f(*args, **kwargs)
           ^^^^^^^^^^^^^^^^^^
  File "/home/airflow/.local/lib/python3.12/site-packages/airflow/cli/commands/task_command.py", line 483, in task_run
    task_return_code = _run_task_by_selected_method(args, _dag, ti)
                       ^^^^^^^^^^^^^^^^^^^^^^^^^^^^^^^^^^^^^^^^^^^^
  File "/home/airflow/.local/lib/python3.12/site-packages/airflow/cli/commands/task_command.py", line 256, in _run_task_by_selected_method
    return _run_raw_task(args, ti)
           ^^^^^^^^^^^^^^^^^^^^^^^
  File "/home/airflow/.local/lib/python3.12/site-packages/airflow/cli/commands/task_command.py", line 341, in _run_raw_task
    return ti._run_raw_task(
           ^^^^^^^^^^^^^^^^^
  File "/home/airflow/.local/lib/python3.12/site-packages/airflow/utils/session.py", line 97, in wrapper
    return func(*args, session=session, **kwargs)
           ^^^^^^^^^^^^^^^^^^^^^^^^^^^^^^^^^^^^^^
  File "/home/airflow/.local/lib/python3.12/site-packages/airflow/models/taskinstance.py", line 3005, in _run_raw_task
    return _run_raw_task(
           ^^^^^^^^^^^^^^
  File "/home/airflow/.local/lib/python3.12/site-packages/airflow/models/taskinstance.py", line 273, in _run_raw_task
    TaskInstance._execute_task_with_callbacks(
  File "/home/airflow/.local/lib/python3.12/site-packages/airflow/models/taskinstance.py", line 3159, in _execute_task_with_callbacks
    result = self._execute_task(context, task_orig)
             ^^^^^^^^^^^^^^^^^^^^^^^^^^^^^^^^^^^^^^
  File "/home/airflow/.local/lib/python3.12/site-packages/airflow/models/taskinstance.py", line 3183, in _execute_task
    return _execute_task(self, context, task_orig)
           ^^^^^^^^^^^^^^^^^^^^^^^^^^^^^^^^^^^^^^^
  File "/home/airflow/.local/lib/python3.12/site-packages/airflow/models/taskinstance.py", line 767, in _execute_task
    result = _execute_callable(context=context, **execute_callable_kwargs)
             ^^^^^^^^^^^^^^^^^^^^^^^^^^^^^^^^^^^^^^^^^^^^^^^^^^^^^^^^^^^^^
  File "/home/airflow/.local/lib/python3.12/site-packages/airflow/models/taskinstance.py", line 733, in _execute_callable
    return ExecutionCallableRunner(
           ^^^^^^^^^^^^^^^^^^^^^^^^
  File "/home/airflow/.local/lib/python3.12/site-packages/airflow/utils/operator_helpers.py", line 252, in run
    return self.func(*args, **kwargs)
           ^^^^^^^^^^^^^^^^^^^^^^^^^^
  File "/home/airflow/.local/lib/python3.12/site-packages/airflow/models/baseoperator.py", line 417, in wrapper
    return func(self, *args, **kwargs)
           ^^^^^^^^^^^^^^^^^^^^^^^^^^^
  File "/home/airflow/.local/lib/python3.12/site-packages/airflow/decorators/base.py", line 266, in execute
    return_value = super().execute(context)
                   ^^^^^^^^^^^^^^^^^^^^^^^^
  File "/home/airflow/.local/lib/python3.12/site-packages/airflow/models/baseoperator.py", line 417, in wrapper
    return func(self, *args, **kwargs)
           ^^^^^^^^^^^^^^^^^^^^^^^^^^^
  File "/home/airflow/.local/lib/python3.12/site-packages/airflow/operators/python.py", line 505, in execute
    return super().execute(context=serializable_context)
           ^^^^^^^^^^^^^^^^^^^^^^^^^^^^^^^^^^^^^^^^^^^^^
  File "/home/airflow/.local/lib/python3.12/site-packages/airflow/models/baseoperator.py", line 417, in wrapper
    return func(self, *args, **kwargs)
           ^^^^^^^^^^^^^^^^^^^^^^^^^^^
  File "/home/airflow/.local/lib/python3.12/site-packages/airflow/operators/python.py", line 238, in execute
    return_value = self.execute_callable()
                   ^^^^^^^^^^^^^^^^^^^^^^^
  File "/home/airflow/.local/lib/python3.12/site-packages/airflow/operators/python.py", line 870, in execute_callable
    result = self._execute_python_callable_in_subprocess(python_path)
             ^^^^^^^^^^^^^^^^^^^^^^^^^^^^^^^^^^^^^^^^^^^^^^^^^^^^^^^^
  File "/home/airflow/.local/lib/python3.12/site-packages/airflow/operators/python.py", line 588, in _execute_python_callable_in_subprocess
    raise AirflowException(error_msg) from None
airflow.exceptions.AirflowException: Process returned non-zero exit status 1.
name 'get_current_context' is not defined
[2025-01-01T18:05:23.051+0000] {local_task_job_runner.py:266} INFO - Task exited with return code 1
[2025-01-01T18:05:23.115+0000] {taskinstance.py:3895} INFO - 0 downstream tasks scheduled from follow-on schedule check
[2025-01-01T18:05:23.121+0000] {local_task_job_runner.py:245} INFO - ::endgroup::
