[2025-01-01T21:22:55.564+0000] {local_task_job_runner.py:123} INFO - ::group::Pre task execution logs
[2025-01-01T21:22:55.874+0000] {taskinstance.py:2613} INFO - Dependencies all met for dep_context=non-requeueable deps ti=<TaskInstance: prediction_dag_v1.task_to_fail manual__2025-01-01T21:22:52.459706+00:00 [queued]>
[2025-01-01T21:22:55.888+0000] {taskinstance.py:2613} INFO - Dependencies all met for dep_context=requeueable deps ti=<TaskInstance: prediction_dag_v1.task_to_fail manual__2025-01-01T21:22:52.459706+00:00 [queued]>
[2025-01-01T21:22:55.889+0000] {taskinstance.py:2866} INFO - Starting attempt 1 of 2
[2025-01-01T21:22:55.914+0000] {taskinstance.py:2889} INFO - Executing <Task(_PythonDecoratedOperator): task_to_fail> on 2025-01-01 21:22:52.459706+00:00
[2025-01-01T21:22:55.927+0000] {warnings.py:112} WARNING - /home/***/.local/lib/python3.12/site-packages/***/task/task_runner/standard_task_runner.py:70: DeprecationWarning: This process (pid=655) is multi-threaded, use of fork() may lead to deadlocks in the child.
  pid = os.fork()

[2025-01-01T21:22:55.930+0000] {standard_task_runner.py:104} INFO - Running: ['***', 'tasks', 'run', 'prediction_dag_v1', 'task_to_fail', 'manual__2025-01-01T21:22:52.459706+00:00', '--job-id', '16', '--raw', '--subdir', 'DAGS_FOLDER/02_prediction/02_prediction_v1.py', '--cfg-path', '/tmp/tmpfq7n38wc']
[2025-01-01T21:22:55.931+0000] {standard_task_runner.py:72} INFO - Started process 664 to run task
[2025-01-01T21:22:55.932+0000] {standard_task_runner.py:105} INFO - Job 16: Subtask task_to_fail
[2025-01-01T21:22:55.994+0000] {task_command.py:467} INFO - Running <TaskInstance: prediction_dag_v1.task_to_fail manual__2025-01-01T21:22:52.459706+00:00 [running]> on host 935cb972f608
[2025-01-01T21:22:56.110+0000] {taskinstance.py:3132} INFO - Exporting env vars: AIRFLOW_CTX_DAG_OWNER='cm' AIRFLOW_CTX_DAG_ID='prediction_dag_v1' AIRFLOW_CTX_TASK_ID='task_to_fail' AIRFLOW_CTX_EXECUTION_DATE='2025-01-01T21:22:52.459706+00:00' AIRFLOW_CTX_TRY_NUMBER='1' AIRFLOW_CTX_DAG_RUN_ID='manual__2025-01-01T21:22:52.459706+00:00'
[2025-01-01T21:22:56.112+0000] {logging_mixin.py:190} INFO - Task instance is in running state
[2025-01-01T21:22:56.112+0000] {logging_mixin.py:190} INFO -  Previous state of the Task instance: queued
[2025-01-01T21:22:56.113+0000] {logging_mixin.py:190} INFO - Current task name:task_to_fail state:running start_date:2025-01-01 21:22:55.874783+00:00
[2025-01-01T21:22:56.114+0000] {logging_mixin.py:190} INFO - Dag name:prediction_dag_v1 and current dag run status:running
[2025-01-01T21:22:56.115+0000] {taskinstance.py:731} INFO - ::endgroup::
[2025-01-01T21:22:56.116+0000] {taskinstance.py:3311} ERROR - Task failed with exception
Traceback (most recent call last):
  File "/home/airflow/.local/lib/python3.12/site-packages/airflow/models/taskinstance.py", line 767, in _execute_task
    result = _execute_callable(context=context, **execute_callable_kwargs)
             ^^^^^^^^^^^^^^^^^^^^^^^^^^^^^^^^^^^^^^^^^^^^^^^^^^^^^^^^^^^^^
  File "/home/airflow/.local/lib/python3.12/site-packages/airflow/models/taskinstance.py", line 733, in _execute_callable
    return ExecutionCallableRunner(
           ^^^^^^^^^^^^^^^^^^^^^^^^
  File "/home/airflow/.local/lib/python3.12/site-packages/airflow/utils/operator_helpers.py", line 252, in run
    return self.func(*args, **kwargs)
           ^^^^^^^^^^^^^^^^^^^^^^^^^^
  File "/home/airflow/.local/lib/python3.12/site-packages/airflow/models/baseoperator.py", line 417, in wrapper
    return func(self, *args, **kwargs)
           ^^^^^^^^^^^^^^^^^^^^^^^^^^^
  File "/home/airflow/.local/lib/python3.12/site-packages/airflow/decorators/base.py", line 266, in execute
    return_value = super().execute(context)
                   ^^^^^^^^^^^^^^^^^^^^^^^^
  File "/home/airflow/.local/lib/python3.12/site-packages/airflow/models/baseoperator.py", line 417, in wrapper
    return func(self, *args, **kwargs)
           ^^^^^^^^^^^^^^^^^^^^^^^^^^^
  File "/home/airflow/.local/lib/python3.12/site-packages/airflow/operators/python.py", line 238, in execute
    return_value = self.execute_callable()
                   ^^^^^^^^^^^^^^^^^^^^^^^
  File "/home/airflow/.local/lib/python3.12/site-packages/airflow/operators/python.py", line 256, in execute_callable
    return runner.run(*self.op_args, **self.op_kwargs)
           ^^^^^^^^^^^^^^^^^^^^^^^^^^^^^^^^^^^^^^^^^^^
  File "/home/airflow/.local/lib/python3.12/site-packages/airflow/utils/operator_helpers.py", line 252, in run
    return self.func(*args, **kwargs)
           ^^^^^^^^^^^^^^^^^^^^^^^^^^
  File "/opt/airflow/dags/common/prediction_task.py", line 128, in task_to_fail
    raise AirflowFailException("error")
airflow.exceptions.AirflowFailException: error
[2025-01-01T21:22:56.137+0000] {logging_mixin.py:190} INFO - Task instance in failure state
[2025-01-01T21:22:56.138+0000] {logging_mixin.py:190} INFO - Task start:2025-01-01 21:22:55.874783+00:00 end:2025-01-01 21:22:56.136787+00:00 duration:0.262004
[2025-01-01T21:22:56.139+0000] {logging_mixin.py:190} INFO - Task:<Task(_PythonDecoratedOperator): task_to_fail> dag:<DAG: prediction_dag_v1> dagrun:<DagRun prediction_dag_v1 @ 2025-01-01 21:22:52.459706+00:00: manual__2025-01-01T21:22:52.459706+00:00, state:running, queued_at: 2025-01-01 21:22:52.474550+00:00. externally triggered: True>
[2025-01-01T21:22:56.140+0000] {logging_mixin.py:190} INFO - Failure caused by error
[2025-01-01T21:22:56.141+0000] {taskinstance.py:1225} INFO - Immediate failure requested. Marking task as FAILED. dag_id=prediction_dag_v1, task_id=task_to_fail, run_id=manual__2025-01-01T21:22:52.459706+00:00, execution_date=20250101T212252, start_date=20250101T212255, end_date=20250101T212256
[2025-01-01T21:22:56.158+0000] {taskinstance.py:340} INFO - ::group::Post task execution logs
[2025-01-01T21:22:56.158+0000] {standard_task_runner.py:124} ERROR - Failed to execute job 16 for task task_to_fail (error; 664)
Traceback (most recent call last):
  File "/home/airflow/.local/lib/python3.12/site-packages/airflow/task/task_runner/standard_task_runner.py", line 117, in _start_by_fork
    ret = args.func(args, dag=self.dag)
          ^^^^^^^^^^^^^^^^^^^^^^^^^^^^^
  File "/home/airflow/.local/lib/python3.12/site-packages/airflow/cli/cli_config.py", line 49, in command
    return func(*args, **kwargs)
           ^^^^^^^^^^^^^^^^^^^^^
  File "/home/airflow/.local/lib/python3.12/site-packages/airflow/utils/cli.py", line 116, in wrapper
    return f(*args, **kwargs)
           ^^^^^^^^^^^^^^^^^^
  File "/home/airflow/.local/lib/python3.12/site-packages/airflow/cli/commands/task_command.py", line 483, in task_run
    task_return_code = _run_task_by_selected_method(args, _dag, ti)
                       ^^^^^^^^^^^^^^^^^^^^^^^^^^^^^^^^^^^^^^^^^^^^
  File "/home/airflow/.local/lib/python3.12/site-packages/airflow/cli/commands/task_command.py", line 256, in _run_task_by_selected_method
    return _run_raw_task(args, ti)
           ^^^^^^^^^^^^^^^^^^^^^^^
  File "/home/airflow/.local/lib/python3.12/site-packages/airflow/cli/commands/task_command.py", line 341, in _run_raw_task
    return ti._run_raw_task(
           ^^^^^^^^^^^^^^^^^
  File "/home/airflow/.local/lib/python3.12/site-packages/airflow/utils/session.py", line 97, in wrapper
    return func(*args, session=session, **kwargs)
           ^^^^^^^^^^^^^^^^^^^^^^^^^^^^^^^^^^^^^^
  File "/home/airflow/.local/lib/python3.12/site-packages/airflow/models/taskinstance.py", line 3005, in _run_raw_task
    return _run_raw_task(
           ^^^^^^^^^^^^^^
  File "/home/airflow/.local/lib/python3.12/site-packages/airflow/models/taskinstance.py", line 273, in _run_raw_task
    TaskInstance._execute_task_with_callbacks(
  File "/home/airflow/.local/lib/python3.12/site-packages/airflow/models/taskinstance.py", line 3159, in _execute_task_with_callbacks
    result = self._execute_task(context, task_orig)
             ^^^^^^^^^^^^^^^^^^^^^^^^^^^^^^^^^^^^^^
  File "/home/airflow/.local/lib/python3.12/site-packages/airflow/models/taskinstance.py", line 3183, in _execute_task
    return _execute_task(self, context, task_orig)
           ^^^^^^^^^^^^^^^^^^^^^^^^^^^^^^^^^^^^^^^
  File "/home/airflow/.local/lib/python3.12/site-packages/airflow/models/taskinstance.py", line 767, in _execute_task
    result = _execute_callable(context=context, **execute_callable_kwargs)
             ^^^^^^^^^^^^^^^^^^^^^^^^^^^^^^^^^^^^^^^^^^^^^^^^^^^^^^^^^^^^^
  File "/home/airflow/.local/lib/python3.12/site-packages/airflow/models/taskinstance.py", line 733, in _execute_callable
    return ExecutionCallableRunner(
           ^^^^^^^^^^^^^^^^^^^^^^^^
  File "/home/airflow/.local/lib/python3.12/site-packages/airflow/utils/operator_helpers.py", line 252, in run
    return self.func(*args, **kwargs)
           ^^^^^^^^^^^^^^^^^^^^^^^^^^
  File "/home/airflow/.local/lib/python3.12/site-packages/airflow/models/baseoperator.py", line 417, in wrapper
    return func(self, *args, **kwargs)
           ^^^^^^^^^^^^^^^^^^^^^^^^^^^
  File "/home/airflow/.local/lib/python3.12/site-packages/airflow/decorators/base.py", line 266, in execute
    return_value = super().execute(context)
                   ^^^^^^^^^^^^^^^^^^^^^^^^
  File "/home/airflow/.local/lib/python3.12/site-packages/airflow/models/baseoperator.py", line 417, in wrapper
    return func(self, *args, **kwargs)
           ^^^^^^^^^^^^^^^^^^^^^^^^^^^
  File "/home/airflow/.local/lib/python3.12/site-packages/airflow/operators/python.py", line 238, in execute
    return_value = self.execute_callable()
                   ^^^^^^^^^^^^^^^^^^^^^^^
  File "/home/airflow/.local/lib/python3.12/site-packages/airflow/operators/python.py", line 256, in execute_callable
    return runner.run(*self.op_args, **self.op_kwargs)
           ^^^^^^^^^^^^^^^^^^^^^^^^^^^^^^^^^^^^^^^^^^^
  File "/home/airflow/.local/lib/python3.12/site-packages/airflow/utils/operator_helpers.py", line 252, in run
    return self.func(*args, **kwargs)
           ^^^^^^^^^^^^^^^^^^^^^^^^^^
  File "/opt/airflow/dags/common/prediction_task.py", line 128, in task_to_fail
    raise AirflowFailException("error")
airflow.exceptions.AirflowFailException: error
[2025-01-01T21:22:56.188+0000] {local_task_job_runner.py:266} INFO - Task exited with return code 1
[2025-01-01T21:22:56.200+0000] {local_task_job_runner.py:245} INFO - ::endgroup::
